2025-06-04 20:27:55,924 - INFO - \U0001f680 Запуск бота и инициализация систем...
2025-06-04 20:27:55,926 - INFO - \U0001f6e0 База данных инициализирована
2025-06-04 20:27:55,928 - INFO - \U0001f6ab Чёрный список загружен
2025-06-04 20:27:55,928 - INFO - \U0001f4de Подключение к Telegram...
2025-06-04 20:27:55,928 - INFO - Connecting to 149.154.167.51:443/TcpFull...
2025-06-04 20:27:56,006 - INFO - Connection to 149.154.167.51:443/TcpFull complete!
2025-06-04 20:27:56,540 - WARNING - \u26a0\ufe0f Требуется авторизация через телефон и код
2025-06-04 20:32:38,918 - INFO - \u2705 Авторизован в Telegram
2025-06-04 20:32:39,195 - INFO - \U0001f7e2 Бот запущен и готов к работе
2025-06-04 20:32:39,196 - INFO - Start polling
2025-06-04 20:32:39,413 - INFO - Run polling for bot @LinkProcessorBot id=8008840998 - 'ChanelSVA'
2025-06-04 20:33:31,548 - INFO - \U0001f504 Начинаем парсинг всех активных каналов
2025-06-04 20:33:31,551 - INFO - \U0001f4e1 Обрабатываем канал: NeuralShit
2025-06-04 20:33:31,551 - INFO - \U0001f50d Начинаем парсинг канала: NeuralShit
2025-06-04 20:33:31,840 - ERROR - \U0001f525 Критическая ошибка при парсинге канала 'NeuralShit': object sqlite3.Cursor can't be used in 'await' expression
Traceback (most recent call last):
  File "C:\Users\undyi\Desktop\Python\work\den_oapso_bot\TelegaParserAI\core\parser.py", line 121, in parse_channel
    await cur.execute(
TypeError: object sqlite3.Cursor can't be used in 'await' expression
2025-06-04 20:33:31,841 - INFO - \U0001f4e5 [NeuralShit] Сохранено постов: 0
2025-06-04 20:33:33,839 - INFO - \U0001f4e1 Обрабатываем канал: habr_com
2025-06-04 20:33:33,839 - INFO - \U0001f50d Начинаем парсинг канала: habr_com
2025-06-04 20:33:34,169 - ERROR - \U0001f525 Критическая ошибка при парсинге канала 'habr_com': object sqlite3.Cursor can't be used in 'await' expression
Traceback (most recent call last):
  File "C:\Users\undyi\Desktop\Python\work\den_oapso_bot\TelegaParserAI\core\parser.py", line 121, in parse_channel
    await cur.execute(
TypeError: object sqlite3.Cursor can't be used in 'await' expression
2025-06-04 20:33:34,169 - INFO - \U0001f4e5 [habr_com] Сохранено постов: 0
2025-06-04 20:33:36,176 - INFO - \U0001f4e1 Обрабатываем канал: smartmarket_community
2025-06-04 20:33:36,176 - INFO - \U0001f50d Начинаем парсинг канала: smartmarket_community
2025-06-04 20:33:36,546 - ERROR - \U0001f525 Критическая ошибка при парсинге канала 'smartmarket_community': object sqlite3.Cursor can't be used in 'await' expression
Traceback (most recent call last):
  File "C:\Users\undyi\Desktop\Python\work\den_oapso_bot\TelegaParserAI\core\parser.py", line 121, in parse_channel
    await cur.execute(
TypeError: object sqlite3.Cursor can't be used in 'await' expression
2025-06-04 20:33:36,546 - INFO - \U0001f4e5 [smartmarket_community] Сохранено постов: 0
2025-06-04 20:33:38,560 - INFO - \U0001f4e1 Обрабатываем канал: asf
2025-06-04 20:33:38,561 - INFO - \U0001f50d Начинаем парсинг канала: asf
2025-06-04 20:33:38,701 - ERROR - \u26a0\ufe0f Неожиданная ошибка при получении сущности 'asf': Nobody is using this username, or the username is unacceptable. If the latter, it must match r"[a-zA-Z][\w\d]{3,30}[a-zA-Z\d]" (caused by ResolveUsernameRequest)
Traceback (most recent call last):
  File "C:\Users\undyi\Desktop\Python\work\den_oapso_bot\TelegaParserAI\core\parser.py", line 74, in parse_channel
    entity = await client.get_entity(channel_name)
             ^^^^^^^^^^^^^^^^^^^^^^^^^^^^^^^^^^^^^
  File "C:\Users\undyi\Desktop\Python\work\den_oapso_bot\venv\Lib\site-packages\telethon\client\users.py", line 343, in get_entity
    result.append(await self._get_entity_from_string(x))
                  ^^^^^^^^^^^^^^^^^^^^^^^^^^^^^^^^^^^^^
  File "C:\Users\undyi\Desktop\Python\work\den_oapso_bot\venv\Lib\site-packages\telethon\client\users.py", line 561, in _get_entity_from_string
    result = await self(
             ^^^^^^^^^^^
  File "C:\Users\undyi\Desktop\Python\work\den_oapso_bot\venv\Lib\site-packages\telethon\client\users.py", line 30, in __call__
    return await self._call(self._sender, request, ordered=ordered)
           ^^^^^^^^^^^^^^^^^^^^^^^^^^^^^^^^^^^^^^^^^^^^^^^^^^^^^^^^
  File "C:\Users\undyi\Desktop\Python\work\den_oapso_bot\venv\Lib\site-packages\telethon\client\users.py", line 92, in _call
    result = await future
             ^^^^^^^^^^^^
telethon.errors.rpcerrorlist.UsernameInvalidError: Nobody is using this username, or the username is unacceptable. If the latter, it must match r"[a-zA-Z][\w\d]{3,30}[a-zA-Z\d]" (caused by ResolveUsernameRequest)
2025-06-04 20:33:38,702 - INFO - \U0001f4e5 [asf] Сохранено постов: 0
2025-06-04 20:33:40,708 - INFO - \U0001f4e1 Обрабатываем канал: hawfhalwfhlaf
2025-06-04 20:33:40,708 - INFO - \U0001f50d Начинаем парсинг канала: hawfhalwfhlaf
2025-06-04 20:33:40,790 - WARNING - \u274c Не удалось получить сущность канала 'hawfhalwfhlaf': No user has "hawfhalwfhlaf" as username
2025-06-04 20:33:40,796 - INFO - \U0001f4e5 [hawfhalwfhlaf] Сохранено постов: 0
2025-06-04 20:33:42,795 - INFO - \U0001f4e1 Обрабатываем канал: erunda
2025-06-04 20:33:42,795 - INFO - \U0001f50d Начинаем парсинг канала: erunda
2025-06-04 20:33:42,891 - ERROR - \u26a0\ufe0f Неожиданная ошибка при получении сущности 'erunda': Nobody is using this username, or the username is unacceptable. If the latter, it must match r"[a-zA-Z][\w\d]{3,30}[a-zA-Z\d]" (caused by ResolveUsernameRequest)
Traceback (most recent call last):
  File "C:\Users\undyi\Desktop\Python\work\den_oapso_bot\TelegaParserAI\core\parser.py", line 74, in parse_channel
    entity = await client.get_entity(channel_name)
             ^^^^^^^^^^^^^^^^^^^^^^^^^^^^^^^^^^^^^
  File "C:\Users\undyi\Desktop\Python\work\den_oapso_bot\venv\Lib\site-packages\telethon\client\users.py", line 343, in get_entity
    result.append(await self._get_entity_from_string(x))
                  ^^^^^^^^^^^^^^^^^^^^^^^^^^^^^^^^^^^^^
  File "C:\Users\undyi\Desktop\Python\work\den_oapso_bot\venv\Lib\site-packages\telethon\client\users.py", line 561, in _get_entity_from_string
    result = await self(
             ^^^^^^^^^^^
  File "C:\Users\undyi\Desktop\Python\work\den_oapso_bot\venv\Lib\site-packages\telethon\client\users.py", line 30, in __call__
    return await self._call(self._sender, request, ordered=ordered)
           ^^^^^^^^^^^^^^^^^^^^^^^^^^^^^^^^^^^^^^^^^^^^^^^^^^^^^^^^
  File "C:\Users\undyi\Desktop\Python\work\den_oapso_bot\venv\Lib\site-packages\telethon\client\users.py", line 92, in _call
    result = await future
             ^^^^^^^^^^^^
telethon.errors.rpcerrorlist.UsernameInvalidError: Nobody is using this username, or the username is unacceptable. If the latter, it must match r"[a-zA-Z][\w\d]{3,30}[a-zA-Z\d]" (caused by ResolveUsernameRequest)
2025-06-04 20:33:42,891 - INFO - \U0001f4e5 [erunda] Сохранено постов: 0
2025-06-04 20:33:44,901 - INFO - \U0001f4e1 Обрабатываем канал: nerdsmedia
2025-06-04 20:33:44,901 - INFO - \U0001f50d Начинаем парсинг канала: nerdsmedia
2025-06-04 20:33:45,139 - ERROR - \U0001f525 Критическая ошибка при парсинге канала 'nerdsmedia': object sqlite3.Cursor can't be used in 'await' expression
Traceback (most recent call last):
  File "C:\Users\undyi\Desktop\Python\work\den_oapso_bot\TelegaParserAI\core\parser.py", line 121, in parse_channel
    await cur.execute(
TypeError: object sqlite3.Cursor can't be used in 'await' expression
2025-06-04 20:33:45,140 - INFO - \U0001f4e5 [nerdsmedia] Сохранено постов: 0
2025-06-04 20:33:47,145 - INFO - \U0001f4e1 Обрабатываем канал:  boost
2025-06-04 20:33:47,145 - INFO - \U0001f50d Начинаем парсинг канала:  boost
2025-06-04 20:33:47,325 - ERROR - \U0001f525 Критическая ошибка при парсинге канала ' boost': object sqlite3.Cursor can't be used in 'await' expression
Traceback (most recent call last):
  File "C:\Users\undyi\Desktop\Python\work\den_oapso_bot\TelegaParserAI\core\parser.py", line 121, in parse_channel
    await cur.execute(
TypeError: object sqlite3.Cursor can't be used in 'await' expression
2025-06-04 20:33:47,325 - INFO - \U0001f4e5 [ boost] Сохранено постов: 0
2025-06-04 20:33:49,328 - INFO - \U0001f4e1 Обрабатываем канал:  username
2025-06-04 20:33:49,328 - INFO - \U0001f50d Начинаем парсинг канала:  username
2025-06-04 20:33:49,540 - ERROR - \U0001f525 Критическая ошибка при парсинге канала ' username': object sqlite3.Cursor can't be used in 'await' expression
Traceback (most recent call last):
  File "C:\Users\undyi\Desktop\Python\work\den_oapso_bot\TelegaParserAI\core\parser.py", line 121, in parse_channel
    await cur.execute(
TypeError: object sqlite3.Cursor can't be used in 'await' expression
2025-06-04 20:33:49,540 - INFO - \U0001f4e5 [ username] Сохранено постов: 0
2025-06-04 20:33:51,537 - INFO - \U0001f4e1 Обрабатываем канал:  its_capitan
2025-06-04 20:33:51,537 - INFO - \U0001f50d Начинаем парсинг канала:  its_capitan
2025-06-04 20:33:51,858 - ERROR - \U0001f525 Критическая ошибка при парсинге канала ' its_capitan': object sqlite3.Cursor can't be used in 'await' expression
Traceback (most recent call last):
  File "C:\Users\undyi\Desktop\Python\work\den_oapso_bot\TelegaParserAI\core\parser.py", line 121, in parse_channel
    await cur.execute(
TypeError: object sqlite3.Cursor can't be used in 'await' expression
2025-06-04 20:33:51,858 - INFO - \U0001f4e5 [ its_capitan] Сохранено постов: 0
2025-06-04 20:33:53,860 - INFO - \U0001f4e1 Обрабатываем канал:  panshikeji
2025-06-04 20:33:53,860 - INFO - \U0001f50d Начинаем парсинг канала:  panshikeji
2025-06-04 20:33:53,943 - WARNING - \u274c Не удалось получить сущность канала ' panshikeji': No user has "panshikeji" as username
2025-06-04 20:33:53,948 - INFO - \U0001f4e5 [ panshikeji] Сохранено постов: 0
2025-06-04 20:33:55,967 - INFO - \u2705 Всего сохранено постов: 0
2025-06-04 20:33:56,069 - INFO - Update id=413876711 is handled. Duration 24750 ms by bot id=8008840998
2025-06-04 20:34:35,906 - INFO - Cannot get difference since the account is not logged in: AuthKeyUnregisteredError
2025-06-04 20:38:50,258 - INFO - Polling stopped
2025-06-04 20:38:50,483 - INFO - Polling stopped for bot @LinkProcessorBot id=8008840998 - 'ChanelSVA'
2025-06-04 20:38:50,483 - INFO - Disconnecting from 149.154.167.51:443/TcpFull...
2025-06-04 20:38:50,483 - INFO - Disconnection from 149.154.167.51:443/TcpFull complete!
2025-06-04 20:38:50,488 - INFO - \U0001f6d1 Бот и клиент Telegram остановлены
